/*!
 * \file except.hpp
 * \brief This header defines various utilities for working with exceptions.
**/
#ifndef INCG_PL_EXCEPT_HPP
#define INCG_PL_EXCEPT_HPP
#include "source_line.hpp" // PL_SOURCE_LINE
#include "current_function.hpp" // PL_CURRENT_FUNCTION
#include "begin_end_macro.hpp" // PL_BEGIN_MACRO, PL_END_MACRO
#include "stringify.hpp" // PL_STRINGIFY
#include <string> // std::string
#include <stdexcept> // std::runtime_error
/*!
 * \def PL_DEFINE_EXCEPTION_TYPE(exceptionTypeIdentifier, baseClass)
 * \brief Defines an exception type. Its name will be exceptionTypeIdentifier
 *        and the base class will be baseClass. The exception type is defined
 *        in the current namespace. This macro makes defining new exception
 *        types a lot more convenient by generating a lot of boilerplate code.
**/

/*!
 * \def PL_THROW_WITH_SOURCE_INFO(exceptionType, message)
 * \brief Throws an exception of type exceptionType with the message message
 *        including information regarding where the exception was thrown.
 * \note Note that the line number may have been manipulated using #line.
 *
 * Includes the file, line and function from where the exception was thrown
 * in the message of the exception object of type exceptionType that can be
 * accessed via the .what() member function. The first parameter of this macro
 * must be an exception type, that type will be the type of the exception
 * thrown by the macro. The second parameter of the macro is the message
 * of the user to include in the exception object's message, std::string must
 * be constructible from message.
**/

/*!
 * \def PL_THROW_IF_NULL(pointer)
 * \brief Throws pl::NullPointerException if the pointer passed in is null.
 * \note Uses PL_THROW_WITH_SOURCE_INFO internally.
 * \see PL_THROW_WITH_SOURCE_INFO
**/

/*!
 * \def PL_NOT_YET_IMPLEMENTED
 * \brief Throws pl::NotYetImplementedException. Can be used to 'implement'
 *        functions that are net yet implmented so that they throw when called.
 * \note Uses PL_THROW_WITH_SOURCE_INFO internally.
 * \see PL_THROW_WITH_SOURCE_INFO
**/

#define PL_DEFINE_EXCEPTION_TYPE(exceptionTypeIdentifier, baseClass) \
    class exceptionTypeIdentifier \
        : public baseClass \
    { \
    public: \
        using this_type = exceptionTypeIdentifier; \
        using base_type = baseClass; \
        \
        explicit exceptionTypeIdentifier(const std::string &what_arg) \
            : base_type{ what_arg } \
        { \
        } \
        \
        explicit exceptionTypeIdentifier(const char *what_arg) \
            : base_type{ what_arg } \
        { \
        } \
        \
    }

#define PL_THROW_WITH_SOURCE_INFO(exceptionType, message) \
    throw exceptionType{ \
        "Message: " \
        + std::string{ message } \
        + "\nexception was thrown at:" \
          "\nfile: " __FILE__ \
          "\nline: " PL_SOURCE_LINE \
          "\nfunction: " \
        + std::string{ PL_CURRENT_FUNCTION } \
    }

#define PL_THROW_IF_NULL(pointer) \
    PL_BEGIN_MACRO \
    if ((pointer) == nullptr) { \
        PL_THROW_WITH_SOURCE_INFO(pl::NullPointerException, \
            PL_STRINGIFY(pointer) " was null!"); \
    } \
    PL_END_MACRO

#define PL_NOT_YET_IMPLEMENTED \
    PL_THROW_WITH_SOURCE_INFO(pl::NotYetImplementedException, \
        "function has not yet been implemented!")

namespace pl
{
class AssertionViolationException
    : public std::runtime_error
{
public:
    using std::runtime_error::runtime_error;
};

class PreconditionViolationException
    : public AssertionViolationException
{
public:
    using AssertionViolationException::AssertionViolationException;
};

class PostconditionViolationException
    : public AssertionViolationException
{
public:
    using AssertionViolationException::AssertionViolationException;
};

class NullPointerException
    : public std::runtime_error
{
public:
    using std::runtime_error::runtime_error;
};

class NotYetImplementedException
    : public std::runtime_error
{
public:
    using std::runtime_error::runtime_error;
};

class AsprintfFailureException
    : public std::runtime_error
{
public:
    using std::runtime_error::runtime_error;
};

class ArithmeticException
    : public std::runtime_error
{
public:
    using std::runtime_error::runtime_error;
};

class IllegalArgumentException
    : public std::runtime_error
{
public:
    using std::runtime_error::runtime_error;
};

class IndexOutOfBoundsException
    : public std::runtime_error
{
public:
    using std::runtime_error::runtime_error;
};

class OperationNotSupportedException
    : public std::runtime_error
{
public:
    using std::runtime_error::runtime_error;
};

class InvalidSizeException
    : public std::runtime_error
{
public:
    using std::runtime_error::runtime_error;
};

/*!
 * \brief Function to handle uncaught exceptions.
 * \warning Only call this function in a catch block!
 * \note This function attempts to rethrow the exception that was just caught.
 * \example int main()
 *          try {
 *              app::throwException();
 *          } catch (...) {
 *              pl::handleExceptions();
 *          }
 *
 * This function can be used to handle uncaught exceptions that would escape
 * from the main function for instance.
 * This function shall be called in a try { } catch (...) { } block.
 * pl::handleException will rethrow the exception that was just caught and
 * handle it, by printing the information associated with that exception to
 * std::cerr.
**/
void handleExceptions();
} // namespace pl
#endif // INCG_PL_EXCEPT_HPP
